Workbook

Sheet Accueil
B2: Plan Financier et Stratégique d'AéroTech Maroc
B3: Analyse financière CGNC · Reporting · Tableau de bord — Exercice 2023
B5: IDENTIFICATION
B6: Nom de l'entreprise | C6: AéroTech Maroc
B7: Secteur | C7: Aéronautique
B8: Date | C8: 31 décembre 2023
B9: Département | C9: Finance
B10: Responsable | C10: Mme Amal Bennani
B12: SOMMAIRE
B13: → Balance | C13: Balance comptable CGNC (classes 1 à 7) sur 12 mois — seul onglet de saisie
B14: → CPC | C14: Compte de produits et charges, modèle normal CGNC, calculé automatiquement
B15: → ESG | C15: État des soldes de gestion : TFR (marge, VA, EBE…) et CAF
B16: → Reporting | C16: Élasticité CA/REX codée par couleur et KPI clés, avec sélecteur de mois
B17: → DASHBOARD | C17: Cartes et graphiques de tendance interactifs (grenat et doré)
B18: → Lecture | C18: Explications vulgarisées de chaque indicateur
B20: MODE D'EMPLOI
B21: 1. Saisissez ou collez vos montants uniquement dans l'onglet « Balance » (chiffres en bleu).
B22: 2. Classes 1 à 5 : solde de fin de mois. Classes 6 et 7 : mouvement du mois (pas le cumul).
B23: 3. Vérifiez que la ligne « Contrôle d'équilibre » de la Balance affiche 0 pour chaque mois.
B24: 4. Le CPC, l'ESG, le Reporting et le Dashboard se recalculent seuls : aucune formule à toucher.
B25: 5. Dans le Reporting (C4) et le Dashboard (D4), choisissez un mois dans la liste pour l'analyser.
B26: 6. Pour comprendre un indicateur ou une couleur, consultez l'onglet « Lecture ».
B27: 7. Pour ajouter un compte : insérez une ligne à l'intérieur du bloc de la Balance (avant la dernière ligne de compte).
B29: CONTRÔLES DE COHÉRENCE (automatiques)
B30: Balance équilibrée (12 mois) | C30: =IF(SUMPRODUCT(ABS(Balance!E77:Q77))<1,"✔ OK","✖ Écart à vérifier") -> ✔ OK
B31: CPC : résultat net (2 méthodes) | C31: =IF(SUMPRODUCT(ABS(CPC!D60:P60))<1,"✔ OK","✖ Écart à vérifier") -> ✔ OK
B32: ESG = CPC (résultat net) | C32: =IF(SUMPRODUCT(ABS(ESG!D43:P43))<1,"✔ OK","✖ Écart à vérifier") -> ✔ OK
B34: LÉGENDE
B35: 1 234 567 | C35: Chiffre en bleu : donnée saisie (modifiable)
B36: 1 234 567 | C36: Chiffre en noir : formule (ne pas modifier)
B37: Décembre | C37: Case dorée : sélecteur de mois (liste déroulante)
B39: Note : Toutes les données chiffrées générées dans ce fichier sont fictives.

Sheet Balance
A1: BALANCE COMPTABLE CGNC — AéroTech Maroc — Exercice 2023 | R1: ⌂ Accueil
A2: Montants en MAD · Classes 1 à 5 : soldes de fin de mois · Classes 6 et 7 : mouvements du mois · Données fictives
A3: Légende : | B3: Chiffres en bleu = données saisies (modifiables). Tous les autres onglets se recalculent automatiquement.
A5: Compte | B5: Intitulé | C5: Classe | D5: Sens | E5: Ouverture 01/01 | F5: Janvier | G5: Février | H5: Mars | I5: Avril | J5: Mai | K5: Juin | L5: Juillet | M5: Août | N5: Septembre | O5: Octobre | P5: Novembre | Q5: Décembre | R5: Total / Clôture
B6: CLASSE 1 — COMPTES DE FINANCEMENT PERMANENT
A7: 1111 | B7: Capital social | C7: =VALUE(LEFT(A7,1)) -> 1 | D7: C | E7: 20000000 | F7: 20000000 | G7: 20000000 | H7: 20000000 | I7: 20000000 | J7: 20000000 | K7: 20000000 | L7: 20000000 | M7: 20000000 | N7: 20000000 | O7: 20000000 | P7: 20000000 | Q7: 20000000 | R7: =Q7 -> 20000000
A8: 1140 | B8: Réserve légale | C8: =VALUE(LEFT(A8,1)) -> 1 | D8: C | E8: 2000000 | F8: 2000000 | G8: 2000000 | H8: 2000000 | I8: 2000000 | J8: 2000000 | K8: 2000000 | L8: 2000000 | M8: 2000000 | N8: 2000000 | O8: 2000000 | P8: 2000000 | Q8: 2000000 | R8: =Q8 -> 2000000
A9: 1161 | B9: Report à nouveau (solde créditeur) | C9: =VALUE(LEFT(A9,1)) -> 1 | D9: C | E9: 10000000 | F9: 10000000 | G9: 10000000 | H9: 10000000 | I9: 10000000 | J9: 10000000 | K9: 10000000 | L9: 10000000 | M9: 10000000 | N9: 10000000 | O9: 10000000 | P9: 10000000 | Q9: 10000000 | R9: =Q9 -> 10000000
A10: 1481 | B10: Emprunts auprès des établissements de crédit | C10: =VALUE(LEFT(A10,1)) -> 1 | D10: C | E10: 24000000 | F10: 23700000 | G10: 23400000 | H10: 23100000 | I10: 22800000 | J10: 22500000 | K10: 22200000 | L10: 21900000 | M10: 21600000 | N10: 21300000 | O10: 21000000 | P10: 20700000 | Q10: 20400000 | R10: =Q10 -> 20400000
B11: CLASSE 2 — COMPTES D'ACTIF IMMOBILISÉ
A12: 2321 | B12: Bâtiments | C12: =VALUE(LEFT(A12,1)) -> 2 | D12: D | E12: 15000000 | F12: 15000000 | G12: 15000000 | H12: 15000000 | I12: 15000000 | J12: 15000000 | K12: 15000000 | L12: 15000000 | M12: 15000000 | N12: 15000000 | O12: 15000000 | P12: 15000000 | Q12: 15000000 | R12: =Q12 -> 15000000
A13: 2332 | B13: Matériel et outillage | C13: =VALUE(LEFT(A13,1)) -> 2 | D13: D | E13: 32000000 | F13: 32000000 | G13: 32000000 | H13: 32120000 | I13: 33920000 | J13: 33920000 | K13: 33920000 | L13: 33920000 | M13: 33920000 | N13: 34015000 | O13: 34015000 | P13: 34015000 | Q13: 34015000 | R13: =Q13 -> 34015000
A14: 2340 | B14: Matériel de transport | C14: =VALUE(LEFT(A14,1)) -> 2 | D14: D | E14: 1600000 | F14: 1600000 | G14: 1600000 | H14: 1600000 | I14: 1600000 | J14: 1600000 | K14: 1600000 | L14: 1600000 | M14: 1600000 | N14: 1600000 | O14: 1200000 | P14: 1200000 | Q14: 1200000 | R14: =Q14 -> 1200000
A15: 2355 | B15: Matériel informatique | C15: =VALUE(LEFT(A15,1)) -> 2 | D15: D | E15: 1400000 | F15: 1400000 | G15: 1400000 | H15: 1400000 | I15: 1400000 | J15: 1400000 | K15: 1400000 | L15: 1400000 | M15: 1400000 | N15: 1400000 | O15: 1400000 | P15: 1400000 | Q15: 1400000 | R15: =Q15 -> 1400000
A16: 2832 | B16: Amortissements des constructions | C16: =VALUE(LEFT(A16,1)) -> 2 | D16: C | E16: 4500000 | F16: 4562500 | G16: 4625000 | H16: 4687500 | I16: 4750000 | J16: 4812500 | K16: 4875000 | L16: 4937500 | M16: 5000000 | N16: 5062500 | O16: 5125000 | P16: 5187500 | Q16: 5250000 | R16: =Q16 -> 5250000
A17: 2833 | B17: Amortissements des installations techniques, matériel et outillage | C17: =VALUE(LEFT(A17,1)) -> 2 | D17: C | E17: 13000000 | F17: 13240000 | G17: 13480000 | H17: 13720000 | I17: 13960000 | J17: 14215000 | K17: 14470000 | L17: 14725000 | M17: 14980000 | N17: 15235000 | O17: 15490000 | P17: 15745000 | Q17: 16000000 | R17: =Q17 -> 16000000
A18: 2834 | B18: Amortissements du matériel de transport | C18: =VALUE(LEFT(A18,1)) -> 2 | D18: C | E18: 800000 | F18: 830000 | G18: 860000 | H18: 890000 | I18: 920000 | J18: 950000 | K18: 980000 | L18: 1010000 | M18: 1040000 | N18: 1070000 | O18: 810000 | P18: 832000 | Q18: 854000 | R18: =Q18 -> 854000
A19: 2835 | B19: Amortissements du mobilier, matériel de bureau et aménagements divers | C19: =VALUE(LEFT(A19,1)) -> 2 | D19: C | E19: 600000 | F19: 650000 | G19: 700000 | H19: 750000 | I19: 800000 | J19: 850000 | K19: 900000 | L19: 950000 | M19: 1000000 | N19: 1050000 | O19: 1100000 | P19: 1150000 | Q19: 1200000 | R19: =Q19 -> 1200000
B20: CLASSE 3 — COMPTES D'ACTIF CIRCULANT
A21: 3121 | B21: Matières premières (titane, aluminium, composites) | C21: =VALUE(LEFT(A21,1)) -> 3 | D21: D | E21: 4500000 | F21: 4491000 | G21: 4366000 | H21: 4559000 | I21: 4515000 | J21: 4677000 | K21: 4667000 | L21: 4643000 | M21: 4598000 | N21: 4534000 | O21: 4300000 | P21: 4489000 | Q21: 4685000 | R21: =Q21 -> 4685000
A22: 3131 | B22: Biens en cours | C22: =VALUE(LEFT(A22,1)) -> 3 | D22: D | E22: 9000000 | F22: 8891000 | G22: 9332000 | H22: 8931000 | I22: 8879000 | J22: 9105000 | K22: 9284000 | L22: 9366000 | M22: 9445000 | N22: 9156000 | O22: 9625000 | P22: 9622000 | Q22: 9450000 | R22: =Q22 -> 9450000
A23: 3151 | B23: Produits finis | C23: =VALUE(LEFT(A23,1)) -> 3 | D23: D | E23: 3000000 | F23: 3010000 | G23: 2916000 | H23: 3138000 | I23: 3036000 | J23: 3116000 | K23: 3072000 | L23: 3122000 | M23: 3106000 | N23: 3165000 | O23: 3110000 | P23: 2992000 | Q23: 3228000 | R23: =Q23 -> 3228000
A24: 3421 | B24: Clients | C24: =VALUE(LEFT(A24,1)) -> 3 | D24: D | E24: 14233000 | F24: 13008000 | G24: 14800000 | H24: 15364000 | I24: 15216000 | J24: 14074000 | K24: 16587000 | L24: 15072000 | M24: 11500000 | N24: 15610000 | O24: 15194000 | P24: 16682000 | Q24: 15516000 | R24: =Q24 -> 15516000
A25: 3455 | B25: État — TVA récupérable | C25: =VALUE(LEFT(A25,1)) -> 3 | D25: D | E25: 300000 | F25: 252000 | G25: 274000 | H25: 307000 | I25: 272000 | J25: 323000 | K25: 339000 | L25: 293000 | M25: 236000 | N25: 279000 | O25: 308000 | P25: 317000 | Q25: 337000 | R25: =Q25 -> 337000
A26: 3942 | B26: Provisions pour dépréciation des clients et comptes rattachés | C26: =VALUE(LEFT(A26,1)) -> 3 | D26: C | E26: 180000 | F26: 180000 | G26: 180000 | H26: 180000 | I26: 180000 | J26: 180000 | K26: 240000 | L26: 240000 | M26: 240000 | N26: 240000 | O26: 240000 | P26: 240000 | Q26: 285000 | R26: =Q26 -> 285000
B27: CLASSE 4 — COMPTES DE PASSIF CIRCULANT
A28: 4411 | B28: Fournisseurs | C28: =VALUE(LEFT(A28,1)) -> 4 | D28: C | E28: 9680000 | F28: 7571000 | G28: 8119000 | H28: 9137000 | I28: 8719000 | J28: 9313000 | K28: 9788000 | L28: 9884000 | M28: 7297000 | N28: 9104000 | O28: 9824000 | P28: 9664000 | Q28: 10985000 | R28: =Q28 -> 10985000
A29: 4432 | B29: Rémunérations dues au personnel | C29: =VALUE(LEFT(A29,1)) -> 4 | D29: C | E29: 180000 | F29: 182000 | G29: 183000 | H29: 184000 | I29: 185000 | J29: 185000 | K29: 186000 | L29: 187000 | M29: 188000 | N29: 188000 | O29: 189000 | P29: 190000 | Q29: 205000 | R29: =Q29 -> 205000
A30: 4441 | B30: Caisse nationale de sécurité sociale | C30: =VALUE(LEFT(A30,1)) -> 4 | D30: C | E30: 320000 | F30: 319000 | G30: 320000 | H30: 322000 | I30: 323000 | J30: 324000 | K30: 326000 | L30: 327000 | M30: 328000 | N30: 329000 | O30: 331000 | P30: 332000 | Q30: 358000 | R30: =Q30 -> 358000
A31: 4453 | B31: État — impôts sur les résultats | C31: =VALUE(LEFT(A31,1)) -> 4 | D31: C | E31: 0 | F31: 93700 | G31: 278300 | H31: 0 | I31: 157100 | J31: 365800 | K31: 0 | L31: 205100 | M31: 258400 | N31: 0 | O31: 266800 | P31: 479300 | Q31: 0 | R31: =Q31 -> 0
A32: 4455 | B32: État — TVA facturée | C32: =VALUE(LEFT(A32,1)) -> 4 | D32: C | E32: 30000 | F32: 215000 | G32: 229000 | H32: 251000 | I32: 238000 | J32: 250000 | K32: 260000 | L32: 246000 | M32: 199000 | N32: 245000 | O32: 263000 | P32: 262000 | Q32: 274000 | R32: =Q32 -> 274000
B33: CLASSE 5 — COMPTES DE TRÉSORERIE
A34: 5141 | B34: Banques (soldes débiteurs) | C34: =VALUE(LEFT(A34,1)) -> 5 | D34: D | E34: 4227000 | F34: 4236000 | G34: 3769300 | H34: 4680000 | I34: 3699900 | J34: 6071100 | K34: 4233600 | L34: 6893400 | M34: 8236500 | N34: 6656300 | O34: 9146000 | P34: 8574000 | Q34: 11360200 | R34: =Q34 -> 11360200
A35: 5161 | B35: Caisse | C35: =VALUE(LEFT(A35,1)) -> 5 | D35: D | E35: 30000 | F35: 30000 | G35: 30000 | H35: 30000 | I35: 30000 | J35: 30000 | K35: 30000 | L35: 30000 | M35: 30000 | N35: 30000 | O35: 30000 | P35: 30000 | Q35: 30000 | R35: =Q35 -> 30000
B36: CLASSE 6 — COMPTES DE CHARGES (mouvements du mois)
A37: 6111 | B37: Achats de marchandises | C37: =VALUE(LEFT(A37,1)) -> 6 | D37: D | F37: 94000 | G37: 100000 | H37: 110000 | I37: 104000 | J37: 109000 | K37: 113000 | L37: 107000 | M37: 87000 | N37: 107000 | O37: 115000 | P37: 114000 | Q37: 119000 | R37: =SUM(F37:Q37) -> 1279000
A38: 6121 | B38: Achats de matières premières | C38: =VALUE(LEFT(A38,1)) -> 6 | D38: D | F38: 2360000 | G38: 2563000 | H38: 2976000 | I38: 2557000 | J38: 3075000 | K38: 2949000 | L38: 2775000 | M38: 2202000 | N38: 2622000 | O38: 2864000 | P38: 3074000 | Q38: 3283000 | R38: =SUM(F38:Q38) -> 33300000
A39: 6122 | B39: Achats de matières et fournitures consommables | C39: =VALUE(LEFT(A39,1)) -> 6 | D39: D | F39: 187000 | G39: 212000 | H39: 220000 | I39: 205000 | J39: 230000 | K39: 234000 | L39: 221000 | M39: 177000 | N39: 212000 | O39: 245000 | P39: 228000 | Q39: 244000 | R39: =SUM(F39:Q39) -> 2615000
A40: 6124 | B40: Variation des stocks de matières et fournitures (±) | C40: =VALUE(LEFT(A40,1)) -> 6 | D40: D | F40: 9000 | G40: 125000 | H40: -193000 | I40: 44000 | J40: -162000 | K40: 10000 | L40: 24000 | M40: 45000 | N40: 64000 | O40: 234000 | P40: -189000 | Q40: -196000 | R40: =SUM(F40:Q40) -> -185000
A41: 6125 | B41: Achats non stockés de matières et fournitures (énergie, eau) | C41: =VALUE(LEFT(A41,1)) -> 6 | D41: D | F41: 218000 | G41: 248000 | H41: 256000 | I41: 240000 | J41: 268000 | K41: 273000 | L41: 258000 | M41: 207000 | N41: 247000 | O41: 285000 | P41: 266000 | Q41: 284000 | R41: =SUM(F41:Q41) -> 3050000
...

Sheet CPC
A1: COMPTE DE PRODUITS ET CHARGES (CPC) — Modèle normal CGNC — 2023 | P1: ⌂ Accueil
A2: Montants en MAD · Calcul automatique mensuel depuis l'onglet Balance (SOMMEPROD par racine de compte) · Données fictives
A4: Réf. | B4: DÉSIGNATION | C4: Comptes | D4: Janvier | E4: Février | F4: Mars | G4: Avril | H4: Mai | I4: Juin | J4: Juillet | K4: Août | L4: Septembre | M4: Octobre | N4: Novembre | O4: Décembre | P4: Exercice 2023
A5: I | B5: PRODUITS D'EXPLOITATION
B6: Ventes de marchandises (en l'état) | C6: 711 | D6: =IFERROR(SUMPRODUCT((LEFT(Balance!$A$6:$A$75,3)="711")*Balance!F$6:F$75),0) -> 127000 | E6: =IFERROR(SUMPRODUCT((LEFT(Balance!$A$6:$A$75,3)="711")*Balance!G$6:G$75),0) -> 135000 | F6: =IFERROR(SUMPRODUCT((LEFT(Balance!$A$6:$A$75,3)="711")*Balance!H$6:H$75),0) -> 148000 | G6: =IFERROR(SUMPRODUCT((LEFT(Balance!$A$6:$A$75,3)="711")*Balance!I$6:I$75),0) -> 140000 | H6: =IFERROR(SUMPRODUCT((LEFT(Balance!$A$6:$A$75,3)="711")*Balance!J$6:J$75),0) -> 147000 | I6: =IFERROR(SUMPRODUCT((LEFT(Balance!$A$6:$A$75,3)="711")*Balance!K$6:K$75),0) -> 153000 | J6: =IFERROR(SUMPRODUCT((LEFT(Balance!$A$6:$A$75,3)="711")*Balance!L$6:L$75),0) -> 145000 | K6: =IFERROR(SUMPRODUCT((LEFT(Balance!$A$6:$A$75,3)="711")*Balance!M$6:M$75),0) -> 117000 | ... O6: =IFERROR(SUMPRODUCT((LEFT(Balance!$A$6:$A$75,3)="711")*Balance!Q$6:Q$75),0) -> 161000 | P6: =SUM(D6:O6) -> 1726000
B7: Ventes de biens et services produits | C7: 712 | D7: =IFERROR(SUMPRODUCT((LEFT(Balance!$A$6:$A$75,3)="712")*Balance!F$6:F$75),0) -> 6333000 | E7: =IFERROR(SUMPRODUCT((LEFT(Balance!$A$6:$A$75,3)="712")*Balance!G$6:G$75),0) -> 6727000 | F7: =IFERROR(SUMPRODUCT((LEFT(Balance!$A$6:$A$75,3)="712")*Balance!H$6:H$75),0) -> 7382000 | G7: =IFERROR(SUMPRODUCT((LEFT(Balance!$A$6:$A$75,3)="712")*Balance!I$6:I$75),0) -> 6999000 | H7: =IFERROR(SUMPRODUCT((LEFT(Balance!$A$6:$A$75,3)="712")*Balance!J$6:J$75),0) -> 7359000 | I7: =IFERROR(SUMPRODUCT((LEFT(Balance!$A$6:$A$75,3)="712")*Balance!K$6:K$75),0) -> 7651000 | J7: =IFERROR(SUMPRODUCT((LEFT(Balance!$A$6:$A$75,3)="712")*Balance!L$6:L$75),0) -> 7233000 | K7: =IFERROR(SUMPRODUCT((LEFT(Balance!$A$6:$A$75,3)="712")*Balance!M$6:M$75),0) -> 5851000 | ... O7: =IFERROR(SUMPRODUCT((LEFT(Balance!$A$6:$A$75,3)="712")*Balance!Q$6:Q$75),0) -> 8059000 | P7: =SUM(D7:O7) -> 86249000
B8: Chiffre d'affaires | D8: =D6+D7 -> 6460000 | E8: =E6+E7 -> 6862000 | F8: =F6+F7 -> 7530000 | G8: =G6+G7 -> 7139000 | H8: =H6+H7 -> 7506000 | I8: =I6+I7 -> 7804000 | J8: =J6+J7 -> 7378000 | K8: =K6+K7 -> 5968000 | ... O8: =O6+O7 -> 8220000 | P8: =SUM(D8:O8) -> 87975000
B9: Variation de stocks de produits (±) | C9: 713 | D9: =IFERROR(SUMPRODUCT((LEFT(Balance!$A$6:$A$75,3)="713")*Balance!F$6:F$75),0) -> -99000 | E9: =IFERROR(SUMPRODUCT((LEFT(Balance!$A$6:$A$75,3)="713")*Balance!G$6:G$75),0) -> 347000 | F9: =IFERROR(SUMPRODUCT((LEFT(Balance!$A$6:$A$75,3)="713")*Balance!H$6:H$75),0) -> -179000 | G9: =IFERROR(SUMPRODUCT((LEFT(Balance!$A$6:$A$75,3)="713")*Balance!I$6:I$75),0) -> -154000 | H9: =IFERROR(SUMPRODUCT((LEFT(Balance!$A$6:$A$75,3)="713")*Balance!J$6:J$75),0) -> 306000 | I9: =IFERROR(SUMPRODUCT((LEFT(Balance!$A$6:$A$75,3)="713")*Balance!K$6:K$75),0) -> 135000 | J9: =IFERROR(SUMPRODUCT((LEFT(Balance!$A$6:$A$75,3)="713")*Balance!L$6:L$75),0) -> 132000 | K9: =IFERROR(SUMPRODUCT((LEFT(Balance!$A$6:$A$75,3)="713")*Balance!M$6:M$75),0) -> 63000 | ... O9: =IFERROR(SUMPRODUCT((LEFT(Balance!$A$6:$A$75,3)="713")*Balance!Q$6:Q$75),0) -> 64000 | P9: =SUM(D9:O9) -> 678000
B10: Immobilisations produites par l'entreprise pour elle-même | C10: 714 | D10: =IFERROR(SUMPRODUCT((LEFT(Balance!$A$6:$A$75,3)="714")*Balance!F$6:F$75),0) -> 0 | E10: =IFERROR(SUMPRODUCT((LEFT(Balance!$A$6:$A$75,3)="714")*Balance!G$6:G$75),0) -> 0 | F10: =IFERROR(SUMPRODUCT((LEFT(Balance!$A$6:$A$75,3)="714")*Balance!H$6:H$75),0) -> 120000 | G10: =IFERROR(SUMPRODUCT((LEFT(Balance!$A$6:$A$75,3)="714")*Balance!I$6:I$75),0) -> 0 | H10: =IFERROR(SUMPRODUCT((LEFT(Balance!$A$6:$A$75,3)="714")*Balance!J$6:J$75),0) -> 0 | I10: =IFERROR(SUMPRODUCT((LEFT(Balance!$A$6:$A$75,3)="714")*Balance!K$6:K$75),0) -> 0 | J10: =IFERROR(SUMPRODUCT((LEFT(Balance!$A$6:$A$75,3)="714")*Balance!L$6:L$75),0) -> 0 | K10: =IFERROR(SUMPRODUCT((LEFT(Balance!$A$6:$A$75,3)="714")*Balance!M$6:M$75),0) -> 0 | ... O10: =IFERROR(SUMPRODUCT((LEFT(Balance!$A$6:$A$75,3)="714")*Balance!Q$6:Q$75),0) -> 0 | P10: =SUM(D10:O10) -> 215000
B11: Subventions d'exploitation | C11: 716 | D11: =IFERROR(SUMPRODUCT((LEFT(Balance!$A$6:$A$75,3)="716")*Balance!F$6:F$75),0) -> 40000 | E11: =IFERROR(SUMPRODUCT((LEFT(Balance!$A$6:$A$75,3)="716")*Balance!G$6:G$75),0) -> 40000 | F11: =IFERROR(SUMPRODUCT((LEFT(Balance!$A$6:$A$75,3)="716")*Balance!H$6:H$75),0) -> 40000 | G11: =IFERROR(SUMPRODUCT((LEFT(Balance!$A$6:$A$75,3)="716")*Balance!I$6:I$75),0) -> 40000 | H11: =IFERROR(SUMPRODUCT((LEFT(Balance!$A$6:$A$75,3)="716")*Balance!J$6:J$75),0) -> 40000 | I11: =IFERROR(SUMPRODUCT((LEFT(Balance!$A$6:$A$75,3)="716")*Balance!K$6:K$75),0) -> 40000 | J11: =IFERROR(SUMPRODUCT((LEFT(Balance!$A$6:$A$75,3)="716")*Balance!L$6:L$75),0) -> 40000 | K11: =IFERROR(SUMPRODUCT((LEFT(Balance!$A$6:$A$75,3)="716")*Balance!M$6:M$75),0) -> 40000 | ... O11: =IFERROR(SUMPRODUCT((LEFT(Balance!$A$6:$A$75,3)="716")*Balance!Q$6:Q$75),0) -> 40000 | P11: =SUM(D11:O11) -> 480000
B12: Autres produits d'exploitation | C12: 718 | D12: =IFERROR(SUMPRODUCT((LEFT(Balance!$A$6:$A$75,3)="718")*Balance!F$6:F$75),0) -> 0 | E12: =IFERROR(SUMPRODUCT((LEFT(Balance!$A$6:$A$75,3)="718")*Balance!G$6:G$75),0) -> 0 | F12: =IFERROR(SUMPRODUCT((LEFT(Balance!$A$6:$A$75,3)="718")*Balance!H$6:H$75),0) -> 0 | G12: =IFERROR(SUMPRODUCT((LEFT(Balance!$A$6:$A$75,3)="718")*Balance!I$6:I$75),0) -> 0 | H12: =IFERROR(SUMPRODUCT((LEFT(Balance!$A$6:$A$75,3)="718")*Balance!J$6:J$75),0) -> 0 | I12: =IFERROR(SUMPRODUCT((LEFT(Balance!$A$6:$A$75,3)="718")*Balance!K$6:K$75),0) -> 0 | J12: =IFERROR(SUMPRODUCT((LEFT(Balance!$A$6:$A$75,3)="718")*Balance!L$6:L$75),0) -> 0 | K12: =IFERROR(SUMPRODUCT((LEFT(Balance!$A$6:$A$75,3)="718")*Balance!M$6:M$75),0) -> 0 | ... O12: =IFERROR(SUMPRODUCT((LEFT(Balance!$A$6:$A$75,3)="718")*Balance!Q$6:Q$75),0) -> 0 | P12: =SUM(D12:O12) -> 0
B13: Reprises d'exploitation ; transferts de charges | C13: 719 | D13: =IFERROR(SUMPRODUCT((LEFT(Balance!$A$6:$A$75,3)="719")*Balance!F$6:F$75),0) -> 25000 | E13: =IFERROR(SUMPRODUCT((LEFT(Balance!$A$6:$A$75,3)="719")*Balance!G$6:G$75),0) -> 25000 | F13: =IFERROR(SUMPRODUCT((LEFT(Balance!$A$6:$A$75,3)="719")*Balance!H$6:H$75),0) -> 25000 | G13: =IFERROR(SUMPRODUCT((LEFT(Balance!$A$6:$A$75,3)="719")*Balance!I$6:I$75),0) -> 25000 | H13: =IFERROR(SUMPRODUCT((LEFT(Balance!$A$6:$A$75,3)="719")*Balance!J$6:J$75),0) -> 25000 | I13: =IFERROR(SUMPRODUCT((LEFT(Balance!$A$6:$A$75,3)="719")*Balance!K$6:K$75),0) -> 25000 | J13: =IFERROR(SUMPRODUCT((LEFT(Balance!$A$6:$A$75,3)="719")*Balance!L$6:L$75),0) -> 25000 | K13: =IFERROR(SUMPRODUCT((LEFT(Balance!$A$6:$A$75,3)="719")*Balance!M$6:M$75),0) -> 25000 | ... O13: =IFERROR(SUMPRODUCT((LEFT(Balance!$A$6:$A$75,3)="719")*Balance!Q$6:Q$75),0) -> 60000 | P13: =SUM(D13:O13) -> 335000
B14: TOTAL I | D14: =D8+D9+D10+D11+D12+D13 -> 6426000 | E14: =E8+E9+E10+E11+E12+E13 -> 7274000 | F14: =F8+F9+F10+F11+F12+F13 -> 7536000 | G14: =G8+G9+G10+G11+G12+G13 -> 7050000 | H14: =H8+H9+H10+H11+H12+H13 -> 7877000 | I14: =I8+I9+I10+I11+I12+I13 -> 8004000 | J14: =J8+J9+J10+J11+J12+J13 -> 7575000 | K14: =K8+K9+K10+K11+K12+K13 -> 6096000 | ... O14: =O8+O9+O10+O11+O12+O13 -> 8384000 | P14: =SUM(D14:O14) -> 89683000
A15: II | B15: CHARGES D'EXPLOITATION
B16: Achats revendus de marchandises | C16: 611 | D16: =IFERROR(SUMPRODUCT((LEFT(Balance!$A$6:$A$75,3)="611")*Balance!F$6:F$75),0) -> 94000 | E16: =IFERROR(SUMPRODUCT((LEFT(Balance!$A$6:$A$75,3)="611")*Balance!G$6:G$75),0) -> 100000 | F16: =IFERROR(SUMPRODUCT((LEFT(Balance!$A$6:$A$75,3)="611")*Balance!H$6:H$75),0) -> 110000 | G16: =IFERROR(SUMPRODUCT((LEFT(Balance!$A$6:$A$75,3)="611")*Balance!I$6:I$75),0) -> 104000 | H16: =IFERROR(SUMPRODUCT((LEFT(Balance!$A$6:$A$75,3)="611")*Balance!J$6:J$75),0) -> 109000 | I16: =IFERROR(SUMPRODUCT((LEFT(Balance!$A$6:$A$75,3)="611")*Balance!K$6:K$75),0) -> 113000 | J16: =IFERROR(SUMPRODUCT((LEFT(Balance!$A$6:$A$75,3)="611")*Balance!L$6:L$75),0) -> 107000 | K16: =IFERROR(SUMPRODUCT((LEFT(Balance!$A$6:$A$75,3)="611")*Balance!M$6:M$75),0) -> 87000 | ... O16: =IFERROR(SUMPRODUCT((LEFT(Balance!$A$6:$A$75,3)="611")*Balance!Q$6:Q$75),0) -> 119000 | P16: =SUM(D16:O16) -> 1279000
B17: Achats consommés de matières et fournitures | C17: 612 | D17: =IFERROR(SUMPRODUCT((LEFT(Balance!$A$6:$A$75,3)="612")*Balance!F$6:F$75),0) -> 3086000 | E17: =IFERROR(SUMPRODUCT((LEFT(Balance!$A$6:$A$75,3)="612")*Balance!G$6:G$75),0) -> 3502000 | F17: =IFERROR(SUMPRODUCT((LEFT(Balance!$A$6:$A$75,3)="612")*Balance!H$6:H$75),0) -> 3625000 | G17: =IFERROR(SUMPRODUCT((LEFT(Balance!$A$6:$A$75,3)="612")*Balance!I$6:I$75),0) -> 3388000 | H17: =IFERROR(SUMPRODUCT((LEFT(Balance!$A$6:$A$75,3)="612")*Balance!J$6:J$75),0) -> 3794000 | I17: =IFERROR(SUMPRODUCT((LEFT(Balance!$A$6:$A$75,3)="612")*Balance!K$6:K$75),0) -> 3855000 | J17: =IFERROR(SUMPRODUCT((LEFT(Balance!$A$6:$A$75,3)="612")*Balance!L$6:L$75),0) -> 3646000 | K17: =IFERROR(SUMPRODUCT((LEFT(Balance!$A$6:$A$75,3)="612")*Balance!M$6:M$75),0) -> 2927000 | ... O17: =IFERROR(SUMPRODUCT((LEFT(Balance!$A$6:$A$75,3)="612")*Balance!Q$6:Q$75),0) -> 4021000 | P17: =SUM(D17:O17) -> 43137000
B18: Autres charges externes | C18: 613 / 614 | D18: =IFERROR(SUMPRODUCT((LEFT(Balance!$A$6:$A$75,3)="613")*Balance!F$6:F$75)+SUMPRODUCT((LEFT(Balance!$A$6:$A$75,3)="614")*Balance!F$6:F$75),0) -> 422000 | E18: =IFERROR(SUMPRODUCT((LEFT(Balance!$A$6:$A$75,3)="613")*Balance!G$6:G$75)+SUMPRODUCT((LEFT(Balance!$A$6:$A$75,3)="614")*Balance!G$6:G$75),0) -> 442000 | F18: =IFERROR(SUMPRODUCT((LEFT(Balance!$A$6:$A$75,3)="613")*Balance!H$6:H$75)+SUMPRODUCT((LEFT(Balance!$A$6:$A$75,3)="614")*Balance!H$6:H$75),0) -> 458000 | G18: =IFERROR(SUMPRODUCT((LEFT(Balance!$A$6:$A$75,3)="613")*Balance!I$6:I$75)+SUMPRODUCT((LEFT(Balance!$A$6:$A$75,3)="614")*Balance!I$6:I$75),0) -> 444000 | H18: =IFERROR(SUMPRODUCT((LEFT(Balance!$A$6:$A$75,3)="613")*Balance!J$6:J$75)+SUMPRODUCT((LEFT(Balance!$A$6:$A$75,3)="614")*Balance!J$6:J$75),0) -> 552000 | I18: =IFERROR(SUMPRODUCT((LEFT(Balance!$A$6:$A$75,3)="613")*Balance!K$6:K$75)+SUMPRODUCT((LEFT(Balance!$A$6:$A$75,3)="614")*Balance!K$6:K$75),0) -> 889000 | J18: =IFERROR(SUMPRODUCT((LEFT(Balance!$A$6:$A$75,3)="613")*Balance!L$6:L$75)+SUMPRODUCT((LEFT(Balance!$A$6:$A$75,3)="614")*Balance!L$6:L$75),0) -> 455000 | K18: =IFERROR(SUMPRODUCT((LEFT(Balance!$A$6:$A$75,3)="613")*Balance!M$6:M$75)+SUMPRODUCT((LEFT(Balance!$A$6:$A$75,3)="614")*Balance!M$6:M$75),0) -> 408000 | ... O18: =IFERROR(SUMPRODUCT((LEFT(Balance!$A$6:$A$75,3)="613")*Balance!Q$6:Q$75)+SUMPRODUCT((LEFT(Balance!$A$6:$A$75,3)="614")*Balance!Q$6:Q$75),0) -> 482000 | P18: =SUM(D18:O18) -> 5946000
B19: Impôts et taxes | C19: 616 | D19: =IFERROR(SUMPRODUCT((LEFT(Balance!$A$6:$A$75,3)="616")*Balance!F$6:F$75),0) -> 25000 | E19: =IFERROR(SUMPRODUCT((LEFT(Balance!$A$6:$A$75,3)="616")*Balance!G$6:G$75),0) -> 25000 | F19: =IFERROR(SUMPRODUCT((LEFT(Balance!$A$6:$A$75,3)="616")*Balance!H$6:H$75),0) -> 25000 | G19: =IFERROR(SUMPRODUCT((LEFT(Balance!$A$6:$A$75,3)="616")*Balance!I$6:I$75),0) -> 25000 | H19: =IFERROR(SUMPRODUCT((LEFT(Balance!$A$6:$A$75,3)="616")*Balance!J$6:J$75),0) -> 25000 | I19: =IFERROR(SUMPRODUCT((LEFT(Balance!$A$6:$A$75,3)="616")*Balance!K$6:K$75),0) -> 25000 | J19: =IFERROR(SUMPRODUCT((LEFT(Balance!$A$6:$A$75,3)="616")*Balance!L$6:L$75),0) -> 25000 | K19: =IFERROR(SUMPRODUCT((LEFT(Balance!$A$6:$A$75,3)="616")*Balance!M$6:M$75),0) -> 25000 | ... O19: =IFERROR(SUMPRODUCT((LEFT(Balance!$A$6:$A$75,3)="616")*Balance!Q$6:Q$75),0) -> 25000 | P19: =SUM(D19:O19) -> 300000
B20: Charges de personnel | C20: 617 | D20: =IFERROR(SUMPRODUCT((LEFT(Balance!$A$6:$A$75,3)="617")*Balance!F$6:F$75),0) -> 1869000 | E20: =IFERROR(SUMPRODUCT((LEFT(Balance!$A$6:$A$75,3)="617")*Balance!G$6:G$75),0) -> 1876000 | F20: =IFERROR(SUMPRODUCT((LEFT(Balance!$A$6:$A$75,3)="617")*Balance!H$6:H$75),0) -> 1884000 | G20: =IFERROR(SUMPRODUCT((LEFT(Balance!$A$6:$A$75,3)="617")*Balance!I$6:I$75),0) -> 1891000 | H20: =IFERROR(SUMPRODUCT((LEFT(Balance!$A$6:$A$75,3)="617")*Balance!J$6:J$75),0) -> 1898000 | I20: =IFERROR(SUMPRODUCT((LEFT(Balance!$A$6:$A$75,3)="617")*Balance!K$6:K$75),0) -> 1906000 | J20: =IFERROR(SUMPRODUCT((LEFT(Balance!$A$6:$A$75,3)="617")*Balance!L$6:L$75),0) -> 1913000 | K20: =IFERROR(SUMPRODUCT((LEFT(Balance!$A$6:$A$75,3)="617")*Balance!M$6:M$75),0) -> 1921000 | ... O20: =IFERROR(SUMPRODUCT((LEFT(Balance!$A$6:$A$75,3)="617")*Balance!Q$6:Q$75),0) -> 2095000 | P20: =SUM(D20:O20) -> 23060000
B21: Autres charges d'exploitation | C21: 618 | D21: =IFERROR(SUMPRODUCT((LEFT(Balance!$A$6:$A$75,3)="618")*Balance!F$6:F$75),0) -> 0 | E21: =IFERROR(SUMPRODUCT((LEFT(Balance!$A$6:$A$75,3)="618")*Balance!G$6:G$75),0) -> 0 | F21: =IFERROR(SUMPRODUCT((LEFT(Balance!$A$6:$A$75,3)="618")*Balance!H$6:H$75),0) -> 0 | G21: =IFERROR(SUMPRODUCT((LEFT(Balance!$A$6:$A$75,3)="618")*Balance!I$6:I$75),0) -> 0 | H21: =IFERROR(SUMPRODUCT((LEFT(Balance!$A$6:$A$75,3)="618")*Balance!J$6:J$75),0) -> 0 | I21: =IFERROR(SUMPRODUCT((LEFT(Balance!$A$6:$A$75,3)="618")*Balance!K$6:K$75),0) -> 0 | J21: =IFERROR(SUMPRODUCT((LEFT(Balance!$A$6:$A$75,3)="618")*Balance!L$6:L$75),0) -> 0 | K21: =IFERROR(SUMPRODUCT((LEFT(Balance!$A$6:$A$75,3)="618")*Balance!M$6:M$75),0) -> 0 | ... O21: =IFERROR(SUMPRODUCT((LEFT(Balance!$A$6:$A$75,3)="618")*Balance!Q$6:Q$75),0) -> 35000 | P21: =SUM(D21:O21) -> 35000
B22: Dotations d'exploitation | C22: 619 | D22: =IFERROR(SUMPRODUCT((LEFT(Balance!$A$6:$A$75,3)="619")*Balance!F$6:F$75),0) -> 382500 | E22: =IFERROR(SUMPRODUCT((LEFT(Balance!$A$6:$A$75,3)="619")*Balance!G$6:G$75),0) -> 382500 | F22: =IFERROR(SUMPRODUCT((LEFT(Balance!$A$6:$A$75,3)="619")*Balance!H$6:H$75),0) -> 382500 | G22: =IFERROR(SUMPRODUCT((LEFT(Balance!$A$6:$A$75,3)="619")*Balance!I$6:I$75),0) -> 382500 | H22: =IFERROR(SUMPRODUCT((LEFT(Balance!$A$6:$A$75,3)="619")*Balance!J$6:J$75),0) -> 397500 | I22: =IFERROR(SUMPRODUCT((LEFT(Balance!$A$6:$A$75,3)="619")*Balance!K$6:K$75),0) -> 457500 | J22: =IFERROR(SUMPRODUCT((LEFT(Balance!$A$6:$A$75,3)="619")*Balance!L$6:L$75),0) -> 397500 | K22: =IFERROR(SUMPRODUCT((LEFT(Balance!$A$6:$A$75,3)="619")*Balance!M$6:M$75),0) -> 397500 | ... O22: =IFERROR(SUMPRODUCT((LEFT(Balance!$A$6:$A$75,3)="619")*Balance!Q$6:Q$75),0) -> 469500 | P22: =SUM(D22:O22) -> 4834000
B23: TOTAL II | D23: =D16+D17+D18+D19+D20+D21+D22 -> 5878500 | E23: =E16+E17+E18+E19+E20+E21+E22 -> 6327500 | F23: =F16+F17+F18+F19+F20+F21+F22 -> 6484500 | G23: =G16+G17+G18+G19+G20+G21+G22 -> 6234500 | H23: =H16+H17+H18+H19+H20+H21+H22 -> 6775500 | I23: =I16+I17+I18+I19+I20+I21+I22 -> 7245500 | J23: =J16+J17+J18+J19+J20+J21+J22 -> 6543500 | K23: =K16+K17+K18+K19+K20+K21+K22 -> 5765500 | ... O23: =O16+O17+O18+O19+O20+O21+O22 -> 7246500 | P23: =SUM(D23:O23) -> 78591000
B24: III. RÉSULTAT D'EXPLOITATION (I − II) | D24: =D14-D23 -> 547500 | E24: =E14-E23 -> 946500 | F24: =F14-F23 -> 1051500 | G24: =G14-G23 -> 815500 | H24: =H14-H23 -> 1101500 | I24: =I14-I23 -> 758500 | J24: =J14-J23 -> 1031500 | K24: =K14-K23 -> 330500 | ... O24: =O14-O23 -> 1137500 | P24: =SUM(D24:O24) -> 11092000
A25: IV | B25: PRODUITS FINANCIERS
B26: Produits des titres de participation et autres titres immobilisés | C26: 732 | D26: =IFERROR(SUMPRODUCT((LEFT(Balance!$A$6:$A$75,3)="732")*Balance!F$6:F$75),0) -> 0 | E26: =IFERROR(SUMPRODUCT((LEFT(Balance!$A$6:$A$75,3)="732")*Balance!G$6:G$75),0) -> 0 | F26: =IFERROR(SUMPRODUCT((LEFT(Balance!$A$6:$A$75,3)="732")*Balance!H$6:H$75),0) -> 0 | G26: =IFERROR(SUMPRODUCT((LEFT(Balance!$A$6:$A$75,3)="732")*Balance!I$6:I$75),0) -> 0 | H26: =IFERROR(SUMPRODUCT((LEFT(Balance!$A$6:$A$75,3)="732")*Balance!J$6:J$75),0) -> 0 | I26: =IFERROR(SUMPRODUCT((LEFT(Balance!$A$6:$A$75,3)="732")*Balance!K$6:K$75),0) -> 0 | J26: =IFERROR(SUMPRODUCT((LEFT(Balance!$A$6:$A$75,3)="732")*Balance!L$6:L$75),0) -> 0 | K26: =IFERROR(SUMPRODUCT((LEFT(Balance!$A$6:$A$75,3)="732")*Balance!M$6:M$75),0) -> 0 | ... O26: =IFERROR(SUMPRODUCT((LEFT(Balance!$A$6:$A$75,3)="732")*Balance!Q$6:Q$75),0) -> 0 | P26: =SUM(D26:O26) -> 0
B27: Gains de change | C27: 733 | D27: =IFERROR(SUMPRODUCT((LEFT(Balance!$A$6:$A$75,3)="733")*Balance!F$6:F$75),0) -> 47000 | E27: =IFERROR(SUMPRODUCT((LEFT(Balance!$A$6:$A$75,3)="733")*Balance!G$6:G$75),0) -> 111000 | F27: =IFERROR(SUMPRODUCT((LEFT(Balance!$A$6:$A$75,3)="733")*Balance!H$6:H$75),0) -> 110000 | G27: =IFERROR(SUMPRODUCT((LEFT(Balance!$A$6:$A$75,3)="733")*Balance!I$6:I$75),0) -> 86000 | H27: =IFERROR(SUMPRODUCT((LEFT(Balance!$A$6:$A$75,3)="733")*Balance!J$6:J$75),0) -> 65000 | I27: =IFERROR(SUMPRODUCT((LEFT(Balance!$A$6:$A$75,3)="733")*Balance!K$6:K$75),0) -> 66000 | J27: =IFERROR(SUMPRODUCT((LEFT(Balance!$A$6:$A$75,3)="733")*Balance!L$6:L$75),0) -> 105000 | K27: =IFERROR(SUMPRODUCT((LEFT(Balance!$A$6:$A$75,3)="733")*Balance!M$6:M$75),0) -> 53000 | ... O27: =IFERROR(SUMPRODUCT((LEFT(Balance!$A$6:$A$75,3)="733")*Balance!Q$6:Q$75),0) -> 105000 | P27: =SUM(D27:O27) -> 961000
B28: Intérêts et autres produits financiers | C28: 738 | D28: =IFERROR(SUMPRODUCT((LEFT(Balance!$A$6:$A$75,3)="738")*Balance!F$6:F$75),0) -> 5000 | E28: =IFERROR(SUMPRODUCT((LEFT(Balance!$A$6:$A$75,3)="738")*Balance!G$6:G$75),0) -> 5000 | F28: =IFERROR(SUMPRODUCT((LEFT(Balance!$A$6:$A$75,3)="738")*Balance!H$6:H$75),0) -> 5000 | G28: =IFERROR(SUMPRODUCT((LEFT(Balance!$A$6:$A$75,3)="738")*Balance!I$6:I$75),0) -> 5000 | H28: =IFERROR(SUMPRODUCT((LEFT(Balance!$A$6:$A$75,3)="738")*Balance!J$6:J$75),0) -> 5000 | I28: =IFERROR(SUMPRODUCT((LEFT(Balance!$A$6:$A$75,3)="738")*Balance!K$6:K$75),0) -> 5000 | J28: =IFERROR(SUMPRODUCT((LEFT(Balance!$A$6:$A$75,3)="738")*Balance!L$6:L$75),0) -> 5000 | K28: =IFERROR(SUMPRODUCT((LEFT(Balance!$A$6:$A$75,3)="738")*Balance!M$6:M$75),0) -> 5000 | ... O28: =IFERROR(SUMPRODUCT((LEFT(Balance!$A$6:$A$75,3)="738")*Balance!Q$6:Q$75),0) -> 5000 | P28: =SUM(D28:O28) -> 60000
B29: Reprises financières ; transferts de charges | C29: 739 | D29: =IFERROR(SUMPRODUCT((LEFT(Balance!$A$6:$A$75,3)="739")*Balance!F$6:F$75),0) -> 0 | E29: =IFERROR(SUMPRODUCT((LEFT(Balance!$A$6:$A$75,3)="739")*Balance!G$6:G$75),0) -> 0 | F29: =IFERROR(SUMPRODUCT((LEFT(Balance!$A$6:$A$75,3)="739")*Balance!H$6:H$75),0) -> 0 | G29: =IFERROR(SUMPRODUCT((LEFT(Balance!$A$6:$A$75,3)="739")*Balance!I$6:I$75),0) -> 0 | H29: =IFERROR(SUMPRODUCT((LEFT(Balance!$A$6:$A$75,3)="739")*Balance!J$6:J$75),0) -> 0 | I29: =IFERROR(SUMPRODUCT((LEFT(Balance!$A$6:$A$75,3)="739")*Balance!K$6:K$75),0) -> 0 | J29: =IFERROR(SUMPRODUCT((LEFT(Balance!$A$6:$A$75,3)="739")*Balance!L$6:L$75),0) -> 0 | K29: =IFERROR(SUMPRODUCT((LEFT(Balance!$A$6:$A$75,3)="739")*Balance!M$6:M$75),0) -> 0 | ... O29: =IFERROR(SUMPRODUCT((LEFT(Balance!$A$6:$A$75,3)="739")*Balance!Q$6:Q$75),0) -> 0 | P29: =SUM(D29:O29) -> 0
B30: TOTAL IV | D30: =D26+D27+D28+D29 -> 52000 | E30: =E26+E27+E28+E29 -> 116000 | F30: =F26+F27+F28+F29 -> 115000 | G30: =G26+G27+G28+G29 -> 91000 | H30: =H26+H27+H28+H29 -> 70000 | I30: =I26+I27+I28+I29 -> 71000 | J30: =J26+J27+J28+J29 -> 110000 | K30: =K26+K27+K28+K29 -> 58000 | ... O30: =O26+O27+O28+O29 -> 110000 | P30: =SUM(D30:O30) -> 1021000
A31: V | B31: CHARGES FINANCIÈRES
B32: Charges d'intérêts | C32: 631 | D32: =IFERROR(SUMPRODUCT((LEFT(Balance!$A$6:$A$75,3)="631")*Balance!F$6:F$75),0) -> 104000 | E32: =IFERROR(SUMPRODUCT((LEFT(Balance!$A$6:$A$75,3)="631")*Balance!G$6:G$75),0) -> 102700 | F32: =IFERROR(SUMPRODUCT((LEFT(Balance!$A$6:$A$75,3)="631")*Balance!H$6:H$75),0) -> 101400 | G32: =IFERROR(SUMPRODUCT((LEFT(Balance!$A$6:$A$75,3)="631")*Balance!I$6:I$75),0) -> 100100 | H32: =IFERROR(SUMPRODUCT((LEFT(Balance!$A$6:$A$75,3)="631")*Balance!J$6:J$75),0) -> 98800 | I32: =IFERROR(SUMPRODUCT((LEFT(Balance!$A$6:$A$75,3)="631")*Balance!K$6:K$75),0) -> 97500 | J32: =IFERROR(SUMPRODUCT((LEFT(Balance!$A$6:$A$75,3)="631")*Balance!L$6:L$75),0) -> 96200 | K32: =IFERROR(SUMPRODUCT((LEFT(Balance!$A$6:$A$75,3)="631")*Balance!M$6:M$75),0) -> 94900 | ... O32: =IFERROR(SUMPRODUCT((LEFT(Balance!$A$6:$A$75,3)="631")*Balance!Q$6:Q$75),0) -> 89700 | P32: =SUM(D32:O32) -> 1162200
B33: Pertes de change | C33: 633 | D33: =IFERROR(SUMPRODUCT((LEFT(Balance!$A$6:$A$75,3)="633")*Balance!F$6:F$75),0) -> 27000 | E33: =IFERROR(SUMPRODUCT((LEFT(Balance!$A$6:$A$75,3)="633")*Balance!G$6:G$75),0) -> 37000 | F33: =IFERROR(SUMPRODUCT((LEFT(Balance!$A$6:$A$75,3)="633")*Balance!H$6:H$75),0) -> 52000 | G33: =IFERROR(SUMPRODUCT((LEFT(Balance!$A$6:$A$75,3)="633")*Balance!I$6:I$75),0) -> 21000 | H33: =IFERROR(SUMPRODUCT((LEFT(Balance!$A$6:$A$75,3)="633")*Balance!J$6:J$75),0) -> 29000 | I33: =IFERROR(SUMPRODUCT((LEFT(Balance!$A$6:$A$75,3)="633")*Balance!K$6:K$75),0) -> 61000 | J33: =IFERROR(SUMPRODUCT((LEFT(Balance!$A$6:$A$75,3)="633")*Balance!L$6:L$75),0) -> 20000 | K33: =IFERROR(SUMPRODUCT((LEFT(Balance!$A$6:$A$75,3)="633")*Balance!M$6:M$75),0) -> 27000 | ... O33: =IFERROR(SUMPRODUCT((LEFT(Balance!$A$6:$A$75,3)="633")*Balance!Q$6:Q$75),0) -> 69000 | P33: =SUM(D33:O33) -> 458000
B34: Autres charges financières | C34: 638 | D34: =IFERROR(SUMPRODUCT((LEFT(Balance!$A$6:$A$75,3)="638")*Balance!F$6:F$75),0) -> 0 | E34: =IFERROR(SUMPRODUCT((LEFT(Balance!$A$6:$A$75,3)="638")*Balance!G$6:G$75),0) -> 0 | F34: =IFERROR(SUMPRODUCT((LEFT(Balance!$A$6:$A$75,3)="638")*Balance!H$6:H$75),0) -> 0 | G34: =IFERROR(SUMPRODUCT((LEFT(Balance!$A$6:$A$75,3)="638")*Balance!I$6:I$75),0) -> 0 | H34: =IFERROR(SUMPRODUCT((LEFT(Balance!$A$6:$A$75,3)="638")*Balance!J$6:J$75),0) -> 0 | I34: =IFERROR(SUMPRODUCT((LEFT(Balance!$A$6:$A$75,3)="638")*Balance!K$6:K$75),0) -> 0 | J34: =IFERROR(SUMPRODUCT((LEFT(Balance!$A$6:$A$75,3)="638")*Balance!L$6:L$75),0) -> 0 | K34: =IFERROR(SUMPRODUCT((LEFT(Balance!$A$6:$A$75,3)="638")*Balance!M$6:M$75),0) -> 0 | ... O34: =IFERROR(SUMPRODUCT((LEFT(Balance!$A$6:$A$75,3)="638")*Balance!Q$6:Q$75),0) -> 0 | P34: =SUM(D34:O34) -> 0
B35: Dotations financières | C35: 639 | D35: =IFERROR(SUMPRODUCT((LEFT(Balance!$A$6:$A$75,3)="639")*Balance!F$6:F$75),0) -> 0 | E35: =IFERROR(SUMPRODUCT((LEFT(Balance!$A$6:$A$75,3)="639")*Balance!G$6:G$75),0) -> 0 | F35: =IFERROR(SUMPRODUCT((LEFT(Balance!$A$6:$A$75,3)="639")*Balance!H$6:H$75),0) -> 0 | G35: =IFERROR(SUMPRODUCT((LEFT(Balance!$A$6:$A$75,3)="639")*Balance!I$6:I$75),0) -> 0 | H35: =IFERROR(SUMPRODUCT((LEFT(Balance!$A$6:$A$75,3)="639")*Balance!J$6:J$75),0) -> 0 | I35: =IFERROR(SUMPRODUCT((LEFT(Balance!$A$6:$A$75,3)="639")*Balance!K$6:K$75),0) -> 0 | J35: =IFERROR(SUMPRODUCT((LEFT(Balance!$A$6:$A$75,3)="639")*Balance!L$6:L$75),0) -> 0 | K35: =IFERROR(SUMPRODUCT((LEFT(Balance!$A$6:$A$75,3)="639")*Balance!M$6:M$75),0) -> 0 | ... O35: =IFERROR(SUMPRODUCT((LEFT(Balance!$A$6:$A$75,3)="639")*Balance!Q$6:Q$75),0) -> 0 | P35: =SUM(D35:O35) -> 0
B36: TOTAL V | D36: =D32+D33+D34+D35 -> 131000 | E36: =E32+E33+E34+E35 -> 139700 | F36: =F32+F33+F34+F35 -> 153400 | G36: =G32+G33+G34+G35 -> 121100 | H36: =H32+H33+H34+H35 -> 127800 | I36: =I32+I33+I34+I35 -> 158500 | J36: =J32+J33+J34+J35 -> 116200 | K36: =K32+K33+K34+K35 -> 121900 | ... O36: =O32+O33+O34+O35 -> 158700 | P36: =SUM(D36:O36) -> 1620200
B37: VI. RÉSULTAT FINANCIER (IV − V) | D37: =D30-D36 -> -79000 | E37: =E30-E36 -> -23700 | F37: =F30-F36 -> -38400 | G37: =G30-G36 -> -30100 | H37: =H30-H36 -> -57800 | I37: =I30-I36 -> -87500 | J37: =J30-J36 -> -6200 | K37: =K30-K36 -> -63900 | ... O37: =O30-O36 -> -48700 | P37: =SUM(D37:O37) -> -599200
B38: VII. RÉSULTAT COURANT (III + VI) | D38: =D24+D37 -> 468500 | E38: =E24+E37 -> 922800 | F38: =F24+F37 -> 1013100 | G38: =G24+G37 -> 785400 | H38: =H24+H37 -> 1043700 | I38: =I24+I37 -> 671000 | J38: =J24+J37 -> 1025300 | K38: =K24+K37 -> 266600 | ... O38: =O24+O37 -> 1088800 | P38: =SUM(D38:O38) -> 10492800
A39: VIII | B39: PRODUITS NON COURANTS
B40: Produits des cessions d'immobilisations | C40: 751 | D40: =IFERROR(SUMPRODUCT((LEFT(Balance!$A$6:$A$75,3)="751")*Balance!F$6:F$75),0) -> 0 | E40: =IFERROR(SUMPRODUCT((LEFT(Balance!$A$6:$A$75,3)="751")*Balance!G$6:G$75),0) -> 0 | F40: =IFERROR(SUMPRODUCT((LEFT(Balance!$A$6:$A$75,3)="751")*Balance!H$6:H$75),0) -> 0 | G40: =IFERROR(SUMPRODUCT((LEFT(Balance!$A$6:$A$75,3)="751")*Balance!I$6:I$75),0) -> 0 | H40: =IFERROR(SUMPRODUCT((LEFT(Balance!$A$6:$A$75,3)="751")*Balance!J$6:J$75),0) -> 0 | I40: =IFERROR(SUMPRODUCT((LEFT(Balance!$A$6:$A$75,3)="751")*Balance!K$6:K$75),0) -> 0 | J40: =IFERROR(SUMPRODUCT((LEFT(Balance!$A$6:$A$75,3)="751")*Balance!L$6:L$75),0) -> 0 | K40: =IFERROR(SUMPRODUCT((LEFT(Balance!$A$6:$A$75,3)="751")*Balance!M$6:M$75),0) -> 0 | ... O40: =IFERROR(SUMPRODUCT((LEFT(Balance!$A$6:$A$75,3)="751")*Balance!Q$6:Q$75),0) -> 0 | P40: =SUM(D40:O40) -> 150000
B41: Subventions d'équilibre | C41: 756 | D41: =IFERROR(SUMPRODUCT((LEFT(Balance!$A$6:$A$75,3)="756")*Balance!F$6:F$75),0) -> 0 | E41: =IFERROR(SUMPRODUCT((LEFT(Balance!$A$6:$A$75,3)="756")*Balance!G$6:G$75),0) -> 0 | F41: =IFERROR(SUMPRODUCT((LEFT(Balance!$A$6:$A$75,3)="756")*Balance!H$6:H$75),0) -> 0 | G41: =IFERROR(SUMPRODUCT((LEFT(Balance!$A$6:$A$75,3)="756")*Balance!I$6:I$75),0) -> 0 | H41: =IFERROR(SUMPRODUCT((LEFT(Balance!$A$6:$A$75,3)="756")*Balance!J$6:J$75),0) -> 0 | I41: =IFERROR(SUMPRODUCT((LEFT(Balance!$A$6:$A$75,3)="756")*Balance!K$6:K$75),0) -> 0 | J41: =IFERROR(SUMPRODUCT((LEFT(Balance!$A$6:$A$75,3)="756")*Balance!L$6:L$75),0) -> 0 | K41: =IFERROR(SUMPRODUCT((LEFT(Balance!$A$6:$A$75,3)="756")*Balance!M$6:M$75),0) -> 0 | ... O41: =IFERROR(SUMPRODUCT((LEFT(Balance!$A$6:$A$75,3)="756")*Balance!Q$6:Q$75),0) -> 0 | P41: =SUM(D41:O41) -> 0
...

Sheet ESG
A1: ÉTAT DES SOLDES DE GESTION (ESG) — CGNC — 2023 | P1: ⌂ Accueil
A2: Montants en MAD · Calcul automatique mensuel depuis le CPC et la Balance · Données fictives
A4: Réf. | B4: DÉSIGNATION | C4: Source | D4: Janvier | E4: Février | F4: Mars | G4: Avril | H4: Mai | I4: Juin | J4: Juillet | K4: Août | L4: Septembre | M4: Octobre | N4: Novembre | O4: Décembre | P4: Exercice 2023
A5: A | B5: TABLEAU DE FORMATION DES RÉSULTATS (TFR)
B6: 1. Ventes de marchandises (en l'état) | C6: CPC | D6: =CPC!D6 -> 127000 | E6: =CPC!E6 -> 135000 | F6: =CPC!F6 -> 148000 | G6: =CPC!G6 -> 140000 | H6: =CPC!H6 -> 147000 | I6: =CPC!I6 -> 153000 | J6: =CPC!J6 -> 145000 | K6: =CPC!K6 -> 117000 | ... O6: =CPC!O6 -> 161000 | P6: =SUM(D6:O6) -> 1726000
B7: 2. − Achats revendus de marchandises | C7: CPC | D7: =CPC!D16 -> 94000 | E7: =CPC!E16 -> 100000 | F7: =CPC!F16 -> 110000 | G7: =CPC!G16 -> 104000 | H7: =CPC!H16 -> 109000 | I7: =CPC!I16 -> 113000 | J7: =CPC!J16 -> 107000 | K7: =CPC!K16 -> 87000 | ... O7: =CPC!O16 -> 119000 | P7: =SUM(D7:O7) -> 1279000
B8: I. = MARGE BRUTE SUR VENTES EN L'ÉTAT | D8: =D6-D7 -> 33000 | E8: =E6-E7 -> 35000 | F8: =F6-F7 -> 38000 | G8: =G6-G7 -> 36000 | H8: =H6-H7 -> 38000 | I8: =I6-I7 -> 40000 | J8: =J6-J7 -> 38000 | K8: =K6-K7 -> 30000 | ... O8: =O6-O7 -> 42000 | P8: =SUM(D8:O8) -> 447000
B9: 3. Ventes de biens et services produits | C9: CPC | D9: =CPC!D7 -> 6333000 | E9: =CPC!E7 -> 6727000 | F9: =CPC!F7 -> 7382000 | G9: =CPC!G7 -> 6999000 | H9: =CPC!H7 -> 7359000 | I9: =CPC!I7 -> 7651000 | J9: =CPC!J7 -> 7233000 | K9: =CPC!K7 -> 5851000 | ... O9: =CPC!O7 -> 8059000 | P9: =SUM(D9:O9) -> 86249000
B10: 4. Variation de stocks de produits (±) | C10: CPC | D10: =CPC!D9 -> -99000 | E10: =CPC!E9 -> 347000 | F10: =CPC!F9 -> -179000 | G10: =CPC!G9 -> -154000 | H10: =CPC!H9 -> 306000 | I10: =CPC!I9 -> 135000 | J10: =CPC!J9 -> 132000 | K10: =CPC!K9 -> 63000 | ... O10: =CPC!O9 -> 64000 | P10: =SUM(D10:O10) -> 678000
B11: 5. Immobilisations produites par l'entreprise pour elle-même | C11: CPC | D11: =CPC!D10 -> 0 | E11: =CPC!E10 -> 0 | F11: =CPC!F10 -> 120000 | G11: =CPC!G10 -> 0 | H11: =CPC!H10 -> 0 | I11: =CPC!I10 -> 0 | J11: =CPC!J10 -> 0 | K11: =CPC!K10 -> 0 | ... O11: =CPC!O10 -> 0 | P11: =SUM(D11:O11) -> 215000
B12: II. + PRODUCTION DE L'EXERCICE (3 + 4 + 5) | D12: =D9+D10+D11 -> 6234000 | E12: =E9+E10+E11 -> 7074000 | F12: =F9+F10+F11 -> 7323000 | G12: =G9+G10+G11 -> 6845000 | H12: =H9+H10+H11 -> 7665000 | I12: =I9+I10+I11 -> 7786000 | J12: =J9+J10+J11 -> 7365000 | K12: =K9+K10+K11 -> 5914000 | ... O12: =O9+O10+O11 -> 8123000 | P12: =SUM(D12:O12) -> 87142000
B13: 6. Achats consommés de matières et fournitures | C13: CPC | D13: =CPC!D17 -> 3086000 | E13: =CPC!E17 -> 3502000 | F13: =CPC!F17 -> 3625000 | G13: =CPC!G17 -> 3388000 | H13: =CPC!H17 -> 3794000 | I13: =CPC!I17 -> 3855000 | J13: =CPC!J17 -> 3646000 | K13: =CPC!K17 -> 2927000 | ... O13: =CPC!O17 -> 4021000 | P13: =SUM(D13:O13) -> 43137000
B14: 7. Autres charges externes | C14: CPC | D14: =CPC!D18 -> 422000 | E14: =CPC!E18 -> 442000 | F14: =CPC!F18 -> 458000 | G14: =CPC!G18 -> 444000 | H14: =CPC!H18 -> 552000 | I14: =CPC!I18 -> 889000 | J14: =CPC!J18 -> 455000 | K14: =CPC!K18 -> 408000 | ... O14: =CPC!O18 -> 482000 | P14: =SUM(D14:O14) -> 5946000
B15: III. − CONSOMMATION DE L'EXERCICE (6 + 7) | D15: =D13+D14 -> 3508000 | E15: =E13+E14 -> 3944000 | F15: =F13+F14 -> 4083000 | G15: =G13+G14 -> 3832000 | H15: =H13+H14 -> 4346000 | I15: =I13+I14 -> 4744000 | J15: =J13+J14 -> 4101000 | K15: =K13+K14 -> 3335000 | ... O15: =O13+O14 -> 4503000 | P15: =SUM(D15:O15) -> 49083000
B16: IV. = VALEUR AJOUTÉE (I + II − III) | D16: =D8+D12-D15 -> 2759000 | E16: =E8+E12-E15 -> 3165000 | F16: =F8+F12-F15 -> 3278000 | G16: =G8+G12-G15 -> 3049000 | H16: =H8+H12-H15 -> 3357000 | I16: =I8+I12-I15 -> 3082000 | J16: =J8+J12-J15 -> 3302000 | K16: =K8+K12-K15 -> 2609000 | ... O16: =O8+O12-O15 -> 3662000 | P16: =SUM(D16:O16) -> 38506000
B17: 8. + Subventions d'exploitation | C17: CPC | D17: =CPC!D11 -> 40000 | E17: =CPC!E11 -> 40000 | F17: =CPC!F11 -> 40000 | G17: =CPC!G11 -> 40000 | H17: =CPC!H11 -> 40000 | I17: =CPC!I11 -> 40000 | J17: =CPC!J11 -> 40000 | K17: =CPC!K11 -> 40000 | ... O17: =CPC!O11 -> 40000 | P17: =SUM(D17:O17) -> 480000
B18: 9. − Impôts et taxes | C18: CPC | D18: =CPC!D19 -> 25000 | E18: =CPC!E19 -> 25000 | F18: =CPC!F19 -> 25000 | G18: =CPC!G19 -> 25000 | H18: =CPC!H19 -> 25000 | I18: =CPC!I19 -> 25000 | J18: =CPC!J19 -> 25000 | K18: =CPC!K19 -> 25000 | ... O18: =CPC!O19 -> 25000 | P18: =SUM(D18:O18) -> 300000
B19: 10. − Charges de personnel | C19: CPC | D19: =CPC!D20 -> 1869000 | E19: =CPC!E20 -> 1876000 | F19: =CPC!F20 -> 1884000 | G19: =CPC!G20 -> 1891000 | H19: =CPC!H20 -> 1898000 | I19: =CPC!I20 -> 1906000 | J19: =CPC!J20 -> 1913000 | K19: =CPC!K20 -> 1921000 | ... O19: =CPC!O20 -> 2095000 | P19: =SUM(D19:O19) -> 23060000
B20: V. = EXCÉDENT BRUT D'EXPLOITATION (EBE) ou INSUFFISANCE (IBE) | D20: =D16+D17-D18-D19 -> 905000 | E20: =E16+E17-E18-E19 -> 1304000 | F20: =F16+F17-F18-F19 -> 1409000 | G20: =G16+G17-G18-G19 -> 1173000 | H20: =H16+H17-H18-H19 -> 1474000 | I20: =I16+I17-I18-I19 -> 1191000 | J20: =J16+J17-J18-J19 -> 1404000 | K20: =K16+K17-K18-K19 -> 703000 | ... O20: =O16+O17-O18-O19 -> 1582000 | P20: =SUM(D20:O20) -> 15626000
B21: 11. + Autres produits d'exploitation | C21: CPC | D21: =CPC!D12 -> 0 | E21: =CPC!E12 -> 0 | F21: =CPC!F12 -> 0 | G21: =CPC!G12 -> 0 | H21: =CPC!H12 -> 0 | I21: =CPC!I12 -> 0 | J21: =CPC!J12 -> 0 | K21: =CPC!K12 -> 0 | ... O21: =CPC!O12 -> 0 | P21: =SUM(D21:O21) -> 0
B22: 12. − Autres charges d'exploitation | C22: CPC | D22: =CPC!D21 -> 0 | E22: =CPC!E21 -> 0 | F22: =CPC!F21 -> 0 | G22: =CPC!G21 -> 0 | H22: =CPC!H21 -> 0 | I22: =CPC!I21 -> 0 | J22: =CPC!J21 -> 0 | K22: =CPC!K21 -> 0 | ... O22: =CPC!O21 -> 35000 | P22: =SUM(D22:O22) -> 35000
B23: 13. + Reprises d'exploitation, transferts de charges | C23: CPC | D23: =CPC!D13 -> 25000 | E23: =CPC!E13 -> 25000 | F23: =CPC!F13 -> 25000 | G23: =CPC!G13 -> 25000 | H23: =CPC!H13 -> 25000 | I23: =CPC!I13 -> 25000 | J23: =CPC!J13 -> 25000 | K23: =CPC!K13 -> 25000 | ... O23: =CPC!O13 -> 60000 | P23: =SUM(D23:O23) -> 335000
B24: 14. − Dotations d'exploitation | C24: CPC | D24: =CPC!D22 -> 382500 | E24: =CPC!E22 -> 382500 | F24: =CPC!F22 -> 382500 | G24: =CPC!G22 -> 382500 | H24: =CPC!H22 -> 397500 | I24: =CPC!I22 -> 457500 | J24: =CPC!J22 -> 397500 | K24: =CPC!K22 -> 397500 | ... O24: =CPC!O22 -> 469500 | P24: =SUM(D24:O24) -> 4834000
B25: VI. = RÉSULTAT D'EXPLOITATION (+ ou −) | D25: =D20+D21-D22+D23-D24 -> 547500 | E25: =E20+E21-E22+E23-E24 -> 946500 | F25: =F20+F21-F22+F23-F24 -> 1051500 | G25: =G20+G21-G22+G23-G24 -> 815500 | H25: =H20+H21-H22+H23-H24 -> 1101500 | I25: =I20+I21-I22+I23-I24 -> 758500 | J25: =J20+J21-J22+J23-J24 -> 1031500 | K25: =K20+K21-K22+K23-K24 -> 330500 | ... O25: =O20+O21-O22+O23-O24 -> 1137500 | P25: =SUM(D25:O25) -> 11092000
B26: VII. ± RÉSULTAT FINANCIER | C26: CPC | D26: =CPC!D37 -> -79000 | E26: =CPC!E37 -> -23700 | F26: =CPC!F37 -> -38400 | G26: =CPC!G37 -> -30100 | H26: =CPC!H37 -> -57800 | I26: =CPC!I37 -> -87500 | J26: =CPC!J37 -> -6200 | K26: =CPC!K37 -> -63900 | ... O26: =CPC!O37 -> -48700 | P26: =SUM(D26:O26) -> -599200
B27: VIII. = RÉSULTAT COURANT (+ ou −) | D27: =D25+D26 -> 468500 | E27: =E25+E26 -> 922800 | F27: =F25+F26 -> 1013100 | G27: =G25+G26 -> 785400 | H27: =H25+H26 -> 1043700 | I27: =I25+I26 -> 671000 | J27: =J25+J26 -> 1025300 | K27: =K25+K26 -> 266600 | ... O27: =O25+O26 -> 1088800 | P27: =SUM(D27:O27) -> 10492800
B28: IX. ± RÉSULTAT NON COURANT | C28: CPC | D28: =CPC!D52 -> 0 | E28: =CPC!E52 -> 0 | F28: =CPC!F52 -> -20000 | G28: =CPC!G52 -> 0 | H28: =CPC!H52 -> 0 | I28: =CPC!I52 -> 0 | J28: =CPC!J52 -> 0 | K28: =CPC!K52 -> 0 | ... O28: =CPC!O52 -> 0 | P28: =SUM(D28:O28) -> 20000
B29: 15. − Impôts sur les résultats | C29: CPC | D29: =CPC!D54 -> 93700 | E29: =CPC!E54 -> 184600 | F29: =CPC!F54 -> 198600 | G29: =CPC!G54 -> 157100 | H29: =CPC!H54 -> 208700 | I29: =CPC!I54 -> 134200 | J29: =CPC!J54 -> 205100 | K29: =CPC!K54 -> 53300 | ... O29: =CPC!O54 -> 217800 | P29: =SUM(D29:O29) -> 2102600
B30: X. = RÉSULTAT NET DE L'EXERCICE (+ ou −) | D30: =D27+D28-D29 -> 374800 | E30: =E27+E28-E29 -> 738200 | F30: =F27+F28-F29 -> 794500 | G30: =G27+G28-G29 -> 628300 | H30: =H27+H28-H29 -> 835000 | I30: =I27+I28-I29 -> 536800 | J30: =J27+J28-J29 -> 820200 | K30: =K27+K28-K29 -> 213300 | ... O30: =O27+O28-O29 -> 871000 | P30: =SUM(D30:O30) -> 8410200
A31: B | B31: CAPACITÉ D'AUTOFINANCEMENT (CAF) — méthode additive CGNC
B32: 1. Résultat net de l'exercice | C32: ESG | D32: =D30 -> 374800 | E32: =E30 -> 738200 | F32: =F30 -> 794500 | G32: =G30 -> 628300 | H32: =H30 -> 835000 | I32: =I30 -> 536800 | J32: =J30 -> 820200 | K32: =K30 -> 213300 | ... O32: =O30 -> 871000 | P32: =SUM(D32:O32) -> 8410200
B33: 2. + Dotations d'exploitation (hors actif circulant) | C33: Balance | D33: =IFERROR(SUMPRODUCT((LEFT(Balance!$A$6:$A$75,3)="619")*(LEFT(Balance!$A$6:$A$75,4)<>"6196")*(LEFT(Balance!$A$6:$A$75,4)<>"6197")*Balance!F$6:F$75),0) -> 382500 | E33: =IFERROR(SUMPRODUCT((LEFT(Balance!$A$6:$A$75,3)="619")*(LEFT(Balance!$A$6:$A$75,4)<>"6196")*(LEFT(Balance!$A$6:$A$75,4)<>"6197")*Balance!G$6:G$75),0) -> 382500 | F33: =IFERROR(SUMPRODUCT((LEFT(Balance!$A$6:$A$75,3)="619")*(LEFT(Balance!$A$6:$A$75,4)<>"6196")*(LEFT(Balance!$A$6:$A$75,4)<>"6197")*Balance!H$6:H$75),0) -> 382500 | G33: =IFERROR(SUMPRODUCT((LEFT(Balance!$A$6:$A$75,3)="619")*(LEFT(Balance!$A$6:$A$75,4)<>"6196")*(LEFT(Balance!$A$6:$A$75,4)<>"6197")*Balance!I$6:I$75),0) -> 382500 | H33: =IFERROR(SUMPRODUCT((LEFT(Balance!$A$6:$A$75,3)="619")*(LEFT(Balance!$A$6:$A$75,4)<>"6196")*(LEFT(Balance!$A$6:$A$75,4)<>"6197")*Balance!J$6:J$75),0) -> 397500 | I33: =IFERROR(SUMPRODUCT((LEFT(Balance!$A$6:$A$75,3)="619")*(LEFT(Balance!$A$6:$A$75,4)<>"6196")*(LEFT(Balance!$A$6:$A$75,4)<>"6197")*Balance!K$6:K$75),0) -> 397500 | J33: =IFERROR(SUMPRODUCT((LEFT(Balance!$A$6:$A$75,3)="619")*(LEFT(Balance!$A$6:$A$75,4)<>"6196")*(LEFT(Balance!$A$6:$A$75,4)<>"6197")*Balance!L$6:L$75),0) -> 397500 | K33: =IFERROR(SUMPRODUCT((LEFT(Balance!$A$6:$A$75,3)="619")*(LEFT(Balance!$A$6:$A$75,4)<>"6196")*(LEFT(Balance!$A$6:$A$75,4)<>"6197")*Balance!M$6:M$75),0) -> 397500 | ... O33: =IFERROR(SUMPRODUCT((LEFT(Balance!$A$6:$A$75,3)="619")*(LEFT(Balance!$A$6:$A$75,4)<>"6196")*(LEFT(Balance!$A$6:$A$75,4)<>"6197")*Balance!Q$6:Q$75),0) -> 389500 | P33: =SUM(D33:O33) -> 4694000
B34: 3. + Dotations financières | C34: CPC | D34: =CPC!D35 -> 0 | E34: =CPC!E35 -> 0 | F34: =CPC!F35 -> 0 | G34: =CPC!G35 -> 0 | H34: =CPC!H35 -> 0 | I34: =CPC!I35 -> 0 | J34: =CPC!J35 -> 0 | K34: =CPC!K35 -> 0 | ... O34: =CPC!O35 -> 0 | P34: =SUM(D34:O34) -> 0
B35: 4. + Dotations non courantes | C35: CPC | D35: =CPC!D50 -> 0 | E35: =CPC!E50 -> 0 | F35: =CPC!F50 -> 0 | G35: =CPC!G50 -> 0 | H35: =CPC!H50 -> 0 | I35: =CPC!I50 -> 0 | J35: =CPC!J50 -> 0 | K35: =CPC!K50 -> 0 | ... O35: =CPC!O50 -> 0 | P35: =SUM(D35:O35) -> 0
B36: 5. − Reprises d'exploitation (hors actif circulant et transferts de charges) | C36: Balance | D36: =IFERROR(SUMPRODUCT((LEFT(Balance!$A$6:$A$75,3)="719")*(LEFT(Balance!$A$6:$A$75,4)<>"7196")*(LEFT(Balance!$A$6:$A$75,4)<>"7197")*Balance!F$6:F$75),0) -> 0 | E36: =IFERROR(SUMPRODUCT((LEFT(Balance!$A$6:$A$75,3)="719")*(LEFT(Balance!$A$6:$A$75,4)<>"7196")*(LEFT(Balance!$A$6:$A$75,4)<>"7197")*Balance!G$6:G$75),0) -> 0 | F36: =IFERROR(SUMPRODUCT((LEFT(Balance!$A$6:$A$75,3)="719")*(LEFT(Balance!$A$6:$A$75,4)<>"7196")*(LEFT(Balance!$A$6:$A$75,4)<>"7197")*Balance!H$6:H$75),0) -> 0 | G36: =IFERROR(SUMPRODUCT((LEFT(Balance!$A$6:$A$75,3)="719")*(LEFT(Balance!$A$6:$A$75,4)<>"7196")*(LEFT(Balance!$A$6:$A$75,4)<>"7197")*Balance!I$6:I$75),0) -> 0 | H36: =IFERROR(SUMPRODUCT((LEFT(Balance!$A$6:$A$75,3)="719")*(LEFT(Balance!$A$6:$A$75,4)<>"7196")*(LEFT(Balance!$A$6:$A$75,4)<>"7197")*Balance!J$6:J$75),0) -> 0 | I36: =IFERROR(SUMPRODUCT((LEFT(Balance!$A$6:$A$75,3)="719")*(LEFT(Balance!$A$6:$A$75,4)<>"7196")*(LEFT(Balance!$A$6:$A$75,4)<>"7197")*Balance!K$6:K$75),0) -> 0 | J36: =IFERROR(SUMPRODUCT((LEFT(Balance!$A$6:$A$75,3)="719")*(LEFT(Balance!$A$6:$A$75,4)<>"7196")*(LEFT(Balance!$A$6:$A$75,4)<>"7197")*Balance!L$6:L$75),0) -> 0 | K36: =IFERROR(SUMPRODUCT((LEFT(Balance!$A$6:$A$75,3)="719")*(LEFT(Balance!$A$6:$A$75,4)<>"7196")*(LEFT(Balance!$A$6:$A$75,4)<>"7197")*Balance!M$6:M$75),0) -> 0 | ... O36: =IFERROR(SUMPRODUCT((LEFT(Balance!$A$6:$A$75,3)="719")*(LEFT(Balance!$A$6:$A$75,4)<>"7196")*(LEFT(Balance!$A$6:$A$75,4)<>"7197")*Balance!Q$6:Q$75),0) -> 0 | P36: =SUM(D36:O36) -> 0
B37: 6. − Reprises financières | C37: CPC | D37: =CPC!D29 -> 0 | E37: =CPC!E29 -> 0 | F37: =CPC!F29 -> 0 | G37: =CPC!G29 -> 0 | H37: =CPC!H29 -> 0 | I37: =CPC!I29 -> 0 | J37: =CPC!J29 -> 0 | K37: =CPC!K29 -> 0 | ... O37: =CPC!O29 -> 0 | P37: =SUM(D37:O37) -> 0
B38: 7. − Reprises non courantes | C38: CPC | D38: =CPC!D44 -> 0 | E38: =CPC!E44 -> 0 | F38: =CPC!F44 -> 0 | G38: =CPC!G44 -> 0 | H38: =CPC!H44 -> 0 | I38: =CPC!I44 -> 0 | J38: =CPC!J44 -> 0 | K38: =CPC!K44 -> 0 | ... O38: =CPC!O44 -> 0 | P38: =SUM(D38:O38) -> 0
B39: 8. − Produits des cessions d'immobilisations | C39: CPC | D39: =CPC!D40 -> 0 | E39: =CPC!E40 -> 0 | F39: =CPC!F40 -> 0 | G39: =CPC!G40 -> 0 | H39: =CPC!H40 -> 0 | I39: =CPC!I40 -> 0 | J39: =CPC!J40 -> 0 | K39: =CPC!K40 -> 0 | ... O39: =CPC!O40 -> 0 | P39: =SUM(D39:O39) -> 150000
B40: 9. + Valeurs nettes d'amortissements des immobilisations cédées | C40: CPC | D40: =CPC!D47 -> 0 | E40: =CPC!E47 -> 0 | F40: =CPC!F47 -> 0 | G40: =CPC!G47 -> 0 | H40: =CPC!H47 -> 0 | I40: =CPC!I47 -> 0 | J40: =CPC!J47 -> 0 | K40: =CPC!K47 -> 0 | ... O40: =CPC!O47 -> 0 | P40: =SUM(D40:O40) -> 110000
B41: I. CAPACITÉ D'AUTOFINANCEMENT (CAF) | D41: =D32+D33+D34+D35-D36-D37-D38-D39+D40 -> 757300 | E41: =E32+E33+E34+E35-E36-E37-E38-E39+E40 -> 1120700 | F41: =F32+F33+F34+F35-F36-F37-F38-F39+F40 -> 1177000 | G41: =G32+G33+G34+G35-G36-G37-G38-G39+G40 -> 1010800 | H41: =H32+H33+H34+H35-H36-H37-H38-H39+H40 -> 1232500 | I41: =I32+I33+I34+I35-I36-I37-I38-I39+I40 -> 934300 | J41: =J32+J33+J34+J35-J36-J37-J38-J39+J40 -> 1217700 | K41: =K32+K33+K34+K35-K36-K37-K38-K39+K40 -> 610800 | ... O41: =O32+O33+O34+O35-O36-O37-O38-O39+O40 -> 1260500 | P41: =SUM(D41:O41) -> 13064200
...

Sheet Reporting
A1: REPORTING — Indicateurs clés et élasticité CA / REX — 2023 | Q1: ⌂ Accueil
A2: Formules vivantes alimentées par le CPC, l'ESG et la Balance · Choisissez un mois en C4 · Données fictives
A4: ▸ MOIS SÉLECTIONNÉ (sélecteur) | C4: Décembre | D4: ← cliquez sur la cellule et choisissez un mois dans la liste
A5: Seuil « non significatif » : |variation du CA| inférieure à | C5: 0.02
A6: Élasticité « proportionnelle » : borne basse | C6: 0.8
A7: Élasticité « proportionnelle » : borne haute | C7: 1.2
A9: Indicateur | B9: Unité | C9: Repère | D9: Janvier | E9: Février | F9: Mars | G9: Avril | H9: Mai | I9: Juin | J9: Juillet | K9: Août | L9: Septembre | M9: Octobre | N9: Novembre | O9: Décembre | P9: Année 2023 | Q9: Mois sélectionné
A10: 1. ÉLASTICITÉ CA / REX — le résultat d'exploitation suit-il le chiffre d'affaires ?
A11: Chiffre d'affaires | B11: MAD | D11: =CPC!D8 -> 6460000 | E11: =CPC!E8 -> 6862000 | F11: =CPC!F8 -> 7530000 | G11: =CPC!G8 -> 7139000 | H11: =CPC!H8 -> 7506000 | I11: =CPC!I8 -> 7804000 | J11: =CPC!J8 -> 7378000 | K11: =CPC!K8 -> 5968000 | ... P11: =CPC!P8 -> 87975000 | Q11: =IFERROR(INDEX($D11:$O11,MATCH($C$4,$D$9:$O$9,0)),"–") -> 8220000
A12: Variation du CA vs mois précédent | B12: % | D12: – | E12: =IFERROR(E11/D11-1,"–") -> 0.062229102 | F12: =IFERROR(F11/E11-1,"–") -> 0.097347712 | G12: =IFERROR(G11/F11-1,"–") -> -0.051925631 | H12: =IFERROR(H11/G11-1,"–") -> 0.05140776 | I12: =IFERROR(I11/H11-1,"–") -> 0.039701572 | J12: =IFERROR(J11/I11-1,"–") -> -0.054587391 | K12: =IFERROR(K11/J11-1,"–") -> -0.1911087 | L12: =IFERROR(L11/K11-1,"–") -> 0.23106568 | ... O12: =IFERROR(O11/N11-1,"–") -> 0.04487098 | P12: – | Q12: =IFERROR(INDEX($D12:$O12,MATCH($C$4,$D$9:$O$9,0)),"–") -> 0.04487098
A13: Résultat d'exploitation (REX) | B13: MAD | D13: =CPC!D24 -> 547500 | E13: =CPC!E24 -> 946500 | F13: =CPC!F24 -> 1051500 | G13: =CPC!G24 -> 815500 | H13: =CPC!H24 -> 1101500 | I13: =CPC!I24 -> 758500 | J13: =CPC!J24 -> 1031500 | K13: =CPC!K24 -> 330500 | ... P13: =CPC!P24 -> 11092000 | Q13: =IFERROR(INDEX($D13:$O13,MATCH($C$4,$D$9:$O$9,0)),"–") -> 1137500
A14: Variation du REX vs mois précédent | B14: % | D14: – | E14: =IFERROR(E13/D13-1,"–") -> 0.72876712 | F14: =IFERROR(F13/E13-1,"–") -> 0.11093502 | G14: =IFERROR(G13/F13-1,"–") -> -0.22444127 | H14: =IFERROR(H13/G13-1,"–") -> 0.35070509 | I14: =IFERROR(I13/H13-1,"–") -> -0.31139355 | J14: =IFERROR(J13/I13-1,"–") -> 0.3599209 | K14: =IFERROR(K13/J13-1,"–") -> -0.67959283 | L14: =IFERROR(L13/K13-1,"–") -> 1.6369138 | ... O14: =IFERROR(O13/N13-1,"–") -> 0.02247191 | P14: – | Q14: =IFERROR(INDEX($D14:$O14,MATCH($C$4,$D$9:$O$9,0)),"–") -> 0.02247191
A15: Marge d'exploitation (REX / CA) | B15: % | C15: 10 % à 15 % | D15: =IFERROR(D13/D11,0) -> 0.084752322 | E15: =IFERROR(E13/E11,0) -> 0.13793355 | F15: =IFERROR(F13/F11,0) -> 0.13964143 | G15: =IFERROR(G13/G11,0) -> 0.11423169 | H15: =IFERROR(H13/H11,0) -> 0.14674927 | I15: =IFERROR(I13/I11,0) -> 0.097193747 | J15: =IFERROR(J13/J11,0) -> 0.13980754 | K15: =IFERROR(K13/K11,0) -> 0.055378686 | ... P15: =IFERROR(P13/P11,0) -> 0.12608127 | Q15: =IFERROR(INDEX($D15:$O15,MATCH($C$4,$D$9:$O$9,0)),"–") -> 0.138382
A16: Élasticité REX / CA | B16: coef. | C16: > 1 = levier positif | D16: – | E16: =IF(OR(E12="–",E14="–"),"–",IF(OR(ABS(E12)<$C$5,D13<=0),"n.s.",ROUND(E14/E12,1))) -> 11.7 | F16: =IF(OR(F12="–",F14="–"),"–",IF(OR(ABS(F12)<$C$5,E13<=0),"n.s.",ROUND(F14/F12,1))) -> 1.1 | G16: =IF(OR(G12="–",G14="–"),"–",IF(OR(ABS(G12)<$C$5,F13<=0),"n.s.",ROUND(G14/G12,1))) -> 4.3 | H16: =IF(OR(H12="–",H14="–"),"–",IF(OR(ABS(H12)<$C$5,G13<=0),"n.s.",ROUND(H14/H12,1))) -> 6.8 | I16: =IF(OR(I12="–",I14="–"),"–",IF(OR(ABS(I12)<$C$5,H13<=0),"n.s.",ROUND(I14/I12,1))) -> -7.8 | J16: =IF(OR(J12="–",J14="–"),"–",IF(OR(ABS(J12)<$C$5,I13<=0),"n.s.",ROUND(J14/J12,1))) -> -6.6 | K16: =IF(OR(K12="–",K14="–"),"–",IF(OR(ABS(K12)<$C$5,J13<=0),"n.s.",ROUND(K14/K12,1))) -> 3.6 | L16: =IF(OR(L12="–",L14="–"),"–",IF(OR(ABS(L12)<$C$5,K13<=0),"n.s.",ROUND(L14/L12,1))) -> 7.1 | ... O16: =IF(OR(O12="–",O14="–"),"–",IF(OR(ABS(O12)<$C$5,N13<=0),"n.s.",ROUND(O14/O12,1))) -> 0.5 | P16: – | Q16: =IFERROR(INDEX($D16:$O16,MATCH($C$4,$D$9:$O$9,0)),"–") -> 0.5
A17: Lecture de l'élasticité | C17: voir code couleur | D17: – | E17: =IF(E16="–","–",IF(E16="n.s.","n.s.",IF(E12>0,IF(E16>$C$7,"▲ Levier fort",IF(E16>=$C$6,"▲ Proportionnel",IF(E16>0,"▲ Marge érodée","▲ Sens contraire"))),IF(E16>$C$7,"▼ REX chute plus vite",IF(E16>=$C$6,"▼ Proportionnel",IF(E16>0,"▼ REX résiste","▼ REX progresse")))))) -> ▲ Levier fort | F17: =IF(F16="–","–",IF(F16="n.s.","n.s.",IF(F12>0,IF(F16>$C$7,"▲ Levier fort",IF(F16>=$C$6,"▲ Proportionnel",IF(F16>0,"▲ Marge érodée","▲ Sens contraire"))),IF(F16>$C$7,"▼ REX chute plus vite",IF(F16>=$C$6,"▼ Proportionnel",IF(F16>0,"▼ REX résiste","▼ REX progresse")))))) -> ▲ Proportionnel | G17: =IF(G16="–","–",IF(G16="n.s.","n.s.",IF(G12>0,IF(G16>$C$7,"▲ Levier fort",IF(G16>=$C$6,"▲ Proportionnel",IF(G16>0,"▲ Marge érodée","▲ Sens contraire"))),IF(G16>$C$7,"▼ REX chute plus vite",IF(G16>=$C$6,"▼ Proportionnel",IF(G16>0,"▼ REX résiste","▼ REX progresse")))))) -> ▼ REX chute plus vite | H17: =IF(H16="–","–",IF(H16="n.s.","n.s.",IF(H12>0,IF(H16>$C$7,"▲ Levier fort",IF(H16>=$C$6,"▲ Proportionnel",IF(H16>0,"▲ Marge érodée","▲ Sens contraire"))),IF(H16>$C$7,"▼ REX chute plus vite",IF(H16>=$C$6,"▼ Proportionnel",IF(H16>0,"▼ REX résiste","▼ REX progresse")))))) -> ▲ Levier fort | I17: =IF(I16="–","–",IF(I16="n.s.","n.s.",IF(I12>0,IF(I16>$C$7,"▲ Levier fort",IF(I16>=$C$6,"▲ Proportionnel",IF(I16>0,"▲ Marge érodée","▲ Sens contraire"))),IF(I16>$C$7,"▼ REX chute plus vite",IF(I16>=$C$6,"▼ Proportionnel",IF(I16>0,"▼ REX résiste","▼ REX progresse")))))) -> ▲ Sens contraire | J17: =IF(J16="–","–",IF(J16="n.s.","n.s.",IF(J12>0,IF(J16>$C$7,"▲ Levier fort",IF(J16>=$C$6,"▲ Proportionnel",IF(J16>0,"▲ Marge érodée","▲ Sens contraire"))),IF(J16>$C$7,"▼ REX chute plus vite",IF(J16>=$C$6,"▼ Proportionnel",IF(J16>0,"▼ REX résiste","▼ REX progresse")))))) -> ▼ REX progresse | K17: =IF(K16="–","–",IF(K16="n.s.","n.s.",IF(K12>0,IF(K16>$C$7,"▲ Levier fort",IF(K16>=$C$6,"▲ Proportionnel",IF(K16>0,"▲ Marge érodée","▲ Sens contraire"))),IF(K16>$C$7,"▼ REX chute plus vite",IF(K16>=$C$6,"▼ Proportionnel",IF(K16>0,"▼ REX résiste","▼ REX progresse")))))) -> ▼ REX chute plus vite | L17: =IF(L16="–","–",IF(L16="n.s.","n.s.",IF(L12>0,IF(L16>$C$7,"▲ Levier fort",IF(L16>=$C$6,"▲ Proportionnel",IF(L16>0,"▲ Marge érodée","▲ Sens contraire"))),IF(L16>$C$7,"▼ REX chute plus vite",IF(L16>=$C$6,"▼ Proportionnel",IF(L16>0,"▼ REX résiste","▼ REX progresse")))))) -> ▲ Levier fort | ... O17: =IF(O16="–","–",IF(O16="n.s.","n.s.",IF(O12>0,IF(O16>$C$7,"▲ Levier fort",IF(O16>=$C$6,"▲ Proportionnel",IF(O16>0,"▲ Marge érodée","▲ Sens contraire"))),IF(O16>$C$7,"▼ REX chute plus vite",IF(O16>=$C$6,"▼ Proportionnel",IF(O16>0,"▼ REX résiste","▼ REX progresse")))))) -> ▲ Marge érodée | P17: – | Q17: =IFERROR(INDEX($D17:$O17,MATCH($C$4,$D$9:$O$9,0)),"–") -> ▲ Marge érodée
A18: 2. RENTABILITÉ ET PERFORMANCE
A19: Poids de la masse salariale / CA | B19: % | C19: < 30 % | D19: =IFERROR(CPC!D20/D11,0) -> 0.28931889 | E19: =IFERROR(CPC!E20/E11,0) -> 0.27338968 | F19: =IFERROR(CPC!F20/F11,0) -> 0.2501992 | G19: =IFERROR(CPC!G20/G11,0) -> 0.26488304 | H19: =IFERROR(CPC!H20/H11,0) -> 0.25286438 | I19: =IFERROR(CPC!I20/I11,0) -> 0.24423373 | J19: =IFERROR(CPC!J20/J11,0) -> 0.25928436 | K19: =IFERROR(CPC!K20/K11,0) -> 0.32188338 | ... P19: =IFERROR(CPC!P20/P11,0) -> 0.26211992 | Q19: =IFERROR(INDEX($D19:$O19,MATCH($C$4,$D$9:$O$9,0)),"–") -> 0.25486618
